Workbook

Sheet Backlog Consolidé
A1: BACKLOG CONSOLIDÉ — PORTEFEUILLE PROJETS INFORMATIQUES — CYCLE EN V
A2: Dernière mise à jour : 23/04/2026 | Projets actifs : 4 | Items totaux : 60
A4: ID Item | B4: Code Projet | C4: Nom du Projet | D4: Phase Cycle en V | E4: Titre de l'Item | F4: Responsable | G4: Priorité | H4: Effort (j) | I4: Date Début | J4: Date Fin Prévue | K4: Statut | L4: Commentaires
A5: BL-001 | B5: PROJ-001 | C5: Refonte SI Gestion des Incidents | D5: Expression des Besoins | E5: Cartographie des processus de gestion des incidents | F5: M. Dupont | G5: P1 | H5: 8 | I5: 01/03/2025 | J5: 14/03/2025 | K5: Terminé | L5: Livrables validés en atelier métier
A6: BL-002 | B6: PROJ-001 | C6: Refonte SI Gestion des Incidents | D6: Conception Générale | E6: Rédaction du dossier d'architecture applicative cible | F6: M. Dupont | G6: P1 | H6: 13 | I6: 17/03/2025 | J6: 04/04/2025 | K6: En cours | L6: Dépend BL-001
A7: BL-003 | B7: PROJ-001 | C7: Refonte SI Gestion des Incidents | D7: Conception Générale | E7: Revue des interfaces avec les systèmes tiers (ITSM, AD) | F7: Mme Simon | G7: P2 | H7: 5 | I7: 07/04/2025 | J7: 11/04/2025 | K7: A faire | L7: Dépend BL-002
A8: BL-004 | B8: PROJ-001 | C8: Refonte SI Gestion des Incidents | D8: Conception Générale | E8: Validation de l'architecture en COPIL technique | F8: M. Dupont | G8: P1 | H8: 2 | I8: 14/04/2025 | J8: 15/04/2025 | K8: A faire | L8: Nécessite présence DSI
A9: BL-005 | B9: PROJ-001 | C9: Refonte SI Gestion des Incidents | D9: Conception Détaillée | E9: Spécification des API REST entre modules | F9: Equipe Dev | G9: P1 | H9: 10 | I9: 22/04/2025 | J9: 05/05/2025 | K9: A faire | L9: Dépend BL-004
A10: BL-006 | B10: PROJ-001 | C10: Refonte SI Gestion des Incidents | D10: Réalisation | E10: Développement module création et mise à jour des incidents | F10: Equipe Dev | G10: P1 | H10: 20 | I10: 12/05/2025 | J10: 06/06/2025 | K10: A faire | L10: Dépend BL-005
A11: BL-007 | B11: PROJ-001 | C11: Refonte SI Gestion des Incidents | D11: Réalisation | E11: Développement connecteur LDAP / Active Directory | F11: M. Lefort | G11: P2 | H11: 10 | I11: 02/06/2025 | J11: 13/06/2025 | K11: A faire
A12: BL-008 | B12: PROJ-001 | C12: Refonte SI Gestion des Incidents | D12: Intégration | E12: Tests d'intégration entre modules applicatifs | F12: Equipe QA | G12: P1 | H12: 8 | I12: 16/06/2025 | J12: 25/06/2025 | K12: A faire | L12: Dépend BL-006 BL-007
A13: BL-009 | B13: PROJ-001 | C13: Refonte SI Gestion des Incidents | D13: Recette | E13: Rédaction et exécution des cas de test fonctionnels | F13: M. Dupont | G13: P1 | H13: 6 | I13: 30/06/2025 | J13: 07/07/2025 | K13: A faire | L13: Dépend BL-008
A14: BL-010 | B14: PROJ-001 | C14: Refonte SI Gestion des Incidents | D14: Recette | E14: Correction des anomalies bloquantes (sévérité 1 et 2) | F14: Equipe Dev | G14: P1 | H14: 8 | I14: 08/07/2025 | J14: 18/07/2025 | K14: A faire
A15: BL-011 | B15: PROJ-001 | C15: Refonte SI Gestion des Incidents | D15: Recette | E15: Validation et signature du PV de recette | F15: M. Dupont | G15: P1 | H15: 2 | I15: 21/07/2025 | J15: 22/07/2025 | K15: A faire
A16: BL-012 | B16: PROJ-001 | C16: Refonte SI Gestion des Incidents | D16: Déploiement | E16: Mise en production et documentation technique | F16: Equipe Dev | G16: P1 | H16: 5 | I16: 01/09/2025 | J16: 05/09/2025 | K16: A faire
A17: BL-013 | B17: PROJ-001 | C17: Refonte SI Gestion des Incidents | D17: Déploiement | E17: Formation des administrateurs et utilisateurs clés | F17: M. Dupont | G17: P2 | H17: 3 | I17: 08/09/2025 | J17: 10/09/2025 | K17: A faire
A18: BL-014 | B18: PROJ-001 | C18: Refonte SI Gestion des Incidents | D18: Déploiement | E18: Bilan post-déploiement et clôture du projet | F18: M. Dupont | G18: P2 | H18: 2 | I18: 22/09/2025 | J18: 23/09/2025 | K18: A faire
A19: BL-015 | B19: PROJ-001 | C19: Refonte SI Gestion des Incidents | D19: Conception Détaillée | E19: Modélisation UML des classes métier incidents | F19: M. Lefort | G19: P2 | H19: 8 | I19: 22/04/2025 | J19: 02/05/2025 | K19: A faire
A20: BL-016 | B20: PROJ-002 | C20: Migration Data Warehouse Cloud | D20: Expression des Besoins | E20: Atelier recueil des besoins analytiques métier | F20: Mme Martin | G20: P1 | H20: 6 | I20: 01/04/2025 | J20: 08/04/2025 | K20: Terminé | L20: Ateliers réalisés avec 4 directions
A21: BL-017 | B21: PROJ-002 | C21: Migration Data Warehouse Cloud | D21: Expression des Besoins | E21: Inventaire et qualification des sources de données existantes | F21: M. Lefort | G21: P1 | H21: 8 | I21: 01/04/2025 | J21: 10/04/2025 | K21: Terminé | L21: 45 sources identifiées
A22: BL-018 | B22: PROJ-002 | C22: Migration Data Warehouse Cloud | D22: Conception Générale | E22: Modélisation du schéma de données cible (étoile/flocon) | F22: M. Lefort | G22: P1 | H22: 10 | I22: 14/04/2025 | J22: 25/04/2025 | K22: En cours | L22: Dépend BL-016 BL-017
A23: BL-019 | B23: PROJ-002 | C23: Migration Data Warehouse Cloud | D23: Conception Générale | E23: Choix de la plateforme cloud (Azure Synapse vs Databricks) | F23: Mme Martin | G23: P1 | H23: 5 | I23: 14/04/2025 | J23: 18/04/2025 | K23: En cours | L23: POC en cours
A24: BL-020 | B24: PROJ-002 | C24: Migration Data Warehouse Cloud | D24: Conception Détaillée | E24: Conception des pipelines ETL/ELT (Azure Data Factory) | F24: M. Lefort | G24: P2 | H24: 12 | I24: 28/04/2025 | J24: 13/05/2025 | K24: A faire | L24: Dépend BL-018 BL-019
A25: BL-021 | B25: PROJ-002 | C25: Migration Data Warehouse Cloud | D25: Conception Détaillée | E25: Architecture couche Gold/Silver/Bronze (Medallion) | F25: M. Lefort | G25: P1 | H25: 8 | I25: 28/04/2025 | J25: 07/05/2025 | K25: A faire
A26: BL-022 | B26: PROJ-002 | C26: Migration Data Warehouse Cloud | D26: Réalisation | E26: Développement des scripts de migration historique | F26: Equipe Dev | G26: P1 | H26: 20 | I26: 19/05/2025 | J26: 13/06/2025 | K26: A faire | L26: Dépend BL-020
A27: BL-023 | B27: PROJ-002 | C27: Migration Data Warehouse Cloud | D27: Réalisation | E27: Développement des flux temps réel (streaming Kafka) | F27: Equipe Dev | G27: P2 | H27: 15 | I27: 19/05/2025 | J27: 06/06/2025 | K27: A faire
A28: BL-024 | B28: PROJ-002 | C28: Migration Data Warehouse Cloud | D28: Réalisation | E28: Mise en place des règles de qualité des données (DQ) | F28: Mme Martin | G28: P1 | H28: 10 | I28: 16/06/2025 | J28: 27/06/2025 | K28: A faire
A29: BL-025 | B29: PROJ-002 | C29: Migration Data Warehouse Cloud | D29: Intégration | E29: Tests de charge et de performance du DWH | F29: Equipe QA | G29: P1 | H29: 8 | I29: 30/06/2025 | J29: 09/07/2025 | K29: A faire
A30: BL-026 | B30: PROJ-002 | C30: Migration Data Warehouse Cloud | D30: Recette | E30: Validation des données migrées par les équipes métier | F30: Mme Martin | G30: P1 | H30: 10 | I30: 14/07/2025 | J30: 25/07/2025 | K30: A faire
A31: BL-027 | B31: PROJ-002 | C31: Migration Data Warehouse Cloud | D31: Recette | E31: Tests de non-régression des rapports existants | F31: Equipe QA | G31: P2 | H31: 8 | I31: 28/07/2025 | J31: 06/08/2025 | K31: A faire
A32: BL-028 | B32: PROJ-002 | C32: Migration Data Warehouse Cloud | D32: Recette | E32: Correction des écarts de données identifiés | F32: Equipe Dev | G32: P1 | H32: 10 | I32: 11/08/2025 | J32: 22/08/2025 | K32: A faire
A33: BL-029 | B33: PROJ-002 | C33: Migration Data Warehouse Cloud | D33: Déploiement | E33: Bascule progressive vers le nouveau DWH (pilote) | F33: Equipe Dev | G33: P1 | H33: 5 | I33: 01/12/2025 | J33: 05/12/2025 | K33: A faire
A34: BL-030 | B34: PROJ-002 | C34: Migration Data Warehouse Cloud | D34: Déploiement | E34: Mise en production complète et décommissionnement ancien DWH | F34: Equipe Dev | G34: P1 | H34: 5 | I34: 15/12/2025 | J34: 19/12/2025 | K34: A faire
A35: BL-031 | B35: PROJ-003 | C35: Portail Self-Service Utilisateurs | D35: Expression des Besoins | E35: Ateliers de recueil des besoins utilisateurs | F35: M. Bernard | G35: P1 | H35: 5 | I35: 01/01/2025 | J35: 07/01/2025 | K35: Terminé
A36: BL-032 | B36: PROJ-003 | C36: Portail Self-Service Utilisateurs | D36: Expression des Besoins | E36: Maquettage des interfaces (wireframes) | F36: Equipe UX | G36: P1 | H36: 8 | I36: 08/01/2025 | J36: 17/01/2025 | K36: Terminé | L36: Validé COPIL
A37: BL-033 | B37: PROJ-003 | C37: Portail Self-Service Utilisateurs | D37: Conception Générale | E37: Architecture applicative du portail (frontend/backend) | F37: M. Lefort | G37: P1 | H37: 6 | I37: 20/01/2025 | J37: 27/01/2025 | K37: Terminé
A38: BL-034 | B38: PROJ-003 | C38: Portail Self-Service Utilisateurs | D38: Conception Détaillée | E38: Spécification des workflows self-service (reset MDP, création compte) | F38: M. Bernard | G38: P1 | H38: 8 | I38: 28/01/2025 | J38: 06/02/2025 | K38: Terminé
A39: BL-035 | B39: PROJ-003 | C39: Portail Self-Service Utilisateurs | D39: Réalisation | E39: Développement frontend React — pages principales | F39: Equipe Dev | G39: P1 | H39: 20 | I39: 10/02/2025 | J39: 07/03/2025 | K39: Terminé
A40: BL-036 | B40: PROJ-003 | C40: Portail Self-Service Utilisateurs | D40: Réalisation | E40: Développement API backend (Node.js) | F40: Equipe Dev | G40: P1 | H40: 18 | I40: 10/02/2025 | J40: 03/03/2025 | K40: Terminé
A41: BL-037 | B41: PROJ-003 | C41: Portail Self-Service Utilisateurs | D41: Réalisation | E41: Intégration SSO / SAML avec l'Active Directory | F41: M. Lefort | G41: P1 | H41: 10 | I41: 10/03/2025 | J41: 21/03/2025 | K41: Terminé
...

Sheet Tableau de Bord
A1: TABLEAU DE BORD — PORTEFEUILLE PROJETS IT
A3: SYNTHESE GLOBALE DU PORTEFEUILLE
A4: Indicateur | B4: Valeur | C4: % du total
A5: Total items backlog | B5: =COUNTA('Backlog Consolidé'!A5:A64) -> 60
A6: Items Terminés | B6: =COUNTIF('Backlog Consolidé'!K5:K64,"Terminé") -> 16 | C6: =IF(B5=0,0,C5/B5) -> 0
A7: Items En cours | B7: =COUNTIF('Backlog Consolidé'!K5:K64,"En cours") -> 6 | C7: =IF(B5=0,0,C6/B5) -> 0
A8: Items A faire | B8: =COUNTIF('Backlog Consolidé'!K5:K64,"A faire") -> 38 | C8: =IF(B5=0,0,C7/B5) -> 0
A9: Items Bloqués | B9: =COUNTIF('Backlog Consolidé'!K5:K64,"Bloqué") -> 0 | C9: =IF(B5=0,0,C8/B5) -> 0
A10: Items Annulés | B10: =COUNTIF('Backlog Consolidé'!K5:K64,"Annulé") -> 0 | C10: =IF(B5=0,0,C9/B5) -> 0
A11: Effort total estimé (j) | B11: =SUM('Backlog Consolidé'!H5:H64) -> 478
A12: Effort réalisé estimé (j) | B12: =SUMIF('Backlog Consolidé'!K5:K64,"Terminé",'Backlog Consolidé'!H5:H64) -> 136
A13: Effort restant (j) | B13: =C11-C12 -> 0
A14: Taux de complétion (effort) | B14: =IF(C11=0,0,C12/C11) -> 0
A16: AVANCEMENT PAR PROJET
A17: Projet | B17: Nom | C17: Total | D17: Terminé | E17: En cours | F17: A faire | G17: Bloqué | H17: % Terminé
A18: PROJ-001 | B18: Refonte SI Gestion des Incidents | C18: =COUNTIF('Backlog Consolidé'!B5:B64,"PROJ-001") -> 15 | D18: =COUNTIFS('Backlog Consolidé'!B5:B64,"PROJ-001",'Backlog Consolidé'!K5:K64,"Terminé") -> 1 | E18: =COUNTIFS('Backlog Consolidé'!B5:B64,"PROJ-001",'Backlog Consolidé'!K5:K64,"En cours") -> 1 | F18: =COUNTIFS('Backlog Consolidé'!B5:B64,"PROJ-001",'Backlog Consolidé'!K5:K64,"A faire") -> 13 | G18: =COUNTIFS('Backlog Consolidé'!B5:B64,"PROJ-001",'Backlog Consolidé'!K5:K64,"Bloqué") -> 0 | H18: =IF(C18=0,0,D18/C18) -> 0.066666667
A19: PROJ-002 | B19: Migration Data Warehouse Cloud | C19: =COUNTIF('Backlog Consolidé'!B5:B64,"PROJ-002") -> 15 | D19: =COUNTIFS('Backlog Consolidé'!B5:B64,"PROJ-002",'Backlog Consolidé'!K5:K64,"Terminé") -> 2 | E19: =COUNTIFS('Backlog Consolidé'!B5:B64,"PROJ-002",'Backlog Consolidé'!K5:K64,"En cours") -> 2 | F19: =COUNTIFS('Backlog Consolidé'!B5:B64,"PROJ-002",'Backlog Consolidé'!K5:K64,"A faire") -> 11 | G19: =COUNTIFS('Backlog Consolidé'!B5:B64,"PROJ-002",'Backlog Consolidé'!K5:K64,"Bloqué") -> 0 | H19: =IF(C19=0,0,D19/C19) -> 0.13333333
A20: PROJ-003 | B20: Portail Self-Service Utilisateurs | C20: =COUNTIF('Backlog Consolidé'!B5:B64,"PROJ-003") -> 15 | D20: =COUNTIFS('Backlog Consolidé'!B5:B64,"PROJ-003",'Backlog Consolidé'!K5:K64,"Terminé") -> 8 | E20: =COUNTIFS('Backlog Consolidé'!B5:B64,"PROJ-003",'Backlog Consolidé'!K5:K64,"En cours") -> 2 | F20: =COUNTIFS('Backlog Consolidé'!B5:B64,"PROJ-003",'Backlog Consolidé'!K5:K64,"A faire") -> 5 | G20: =COUNTIFS('Backlog Consolidé'!B5:B64,"PROJ-003",'Backlog Consolidé'!K5:K64,"Bloqué") -> 0 | H20: =IF(C20=0,0,D20/C20) -> 0.53333333
A21: PROJ-004 | B21: Tableau de Bord BI / Reporting Exécutif | C21: =COUNTIF('Backlog Consolidé'!B5:B64,"PROJ-004") -> 15 | D21: =COUNTIFS('Backlog Consolidé'!B5:B64,"PROJ-004",'Backlog Consolidé'!K5:K64,"Terminé") -> 5 | E21: =COUNTIFS('Backlog Consolidé'!B5:B64,"PROJ-004",'Backlog Consolidé'!K5:K64,"En cours") -> 1 | F21: =COUNTIFS('Backlog Consolidé'!B5:B64,"PROJ-004",'Backlog Consolidé'!K5:K64,"A faire") -> 9 | G21: =COUNTIFS('Backlog Consolidé'!B5:B64,"PROJ-004",'Backlog Consolidé'!K5:K64,"Bloqué") -> 0 | H21: =IF(C21=0,0,D21/C21) -> 0.33333333
A22: TOTAL | C22: =SUM(C18:C21) -> 60 | D22: =SUM(D18:D21) -> 16 | E22: =SUM(E18:E21) -> 6 | F22: =SUM(F18:F21) -> 38 | G22: =SUM(G18:G21) -> 0 | H22: =IF(C22=0,0,D22/C22) -> 0.26666667
A24: REPARTITION PAR PHASE CYCLE EN V
A25: Phase Cycle en V | B25: Total | C25: Terminé | D25: En cours | E25: A faire | F25: % Terminé
A26: Expression des Besoins | B26: =COUNTIF('Backlog Consolidé'!D5:D64,"Expression des Besoins") -> 7 | C26: =COUNTIFS('Backlog Consolidé'!D5:D64,"Expression des Besoins",'Backlog Consolidé'!K5:K64,"Terminé") -> 7 | D26: =COUNTIFS('Backlog Consolidé'!D5:D64,"Expression des Besoins",'Backlog Consolidé'!K5:K64,"En cours") -> 0 | E26: =COUNTIFS('Backlog Consolidé'!D5:D64,"Expression des Besoins",'Backlog Consolidé'!K5:K64,"A faire") -> 0 | F26: =IF(B26=0,0,C26/B26) -> 1
A27: Conception Générale | B27: =COUNTIF('Backlog Consolidé'!D5:D64,"Conception Générale") -> 7 | C27: =COUNTIFS('Backlog Consolidé'!D5:D64,"Conception Générale",'Backlog Consolidé'!K5:K64,"Terminé") -> 2 | D27: =COUNTIFS('Backlog Consolidé'!D5:D64,"Conception Générale",'Backlog Consolidé'!K5:K64,"En cours") -> 3 | E27: =COUNTIFS('Backlog Consolidé'!D5:D64,"Conception Générale",'Backlog Consolidé'!K5:K64,"A faire") -> 2 | F27: =IF(B27=0,0,C27/B27) -> 0.28571429
A28: Conception Détaillée | B28: =COUNTIF('Backlog Consolidé'!D5:D64,"Conception Détaillée") -> 7 | C28: =COUNTIFS('Backlog Consolidé'!D5:D64,"Conception Détaillée",'Backlog Consolidé'!K5:K64,"Terminé") -> 3 | D28: =COUNTIFS('Backlog Consolidé'!D5:D64,"Conception Détaillée",'Backlog Consolidé'!K5:K64,"En cours") -> 0 | E28: =COUNTIFS('Backlog Consolidé'!D5:D64,"Conception Détaillée",'Backlog Consolidé'!K5:K64,"A faire") -> 4 | F28: =IF(B28=0,0,C28/B28) -> 0.42857143
A29: Réalisation | B29: =COUNTIF('Backlog Consolidé'!D5:D64,"Réalisation") -> 12 | C29: =COUNTIFS('Backlog Consolidé'!D5:D64,"Réalisation",'Backlog Consolidé'!K5:K64,"Terminé") -> 3 | D29: =COUNTIFS('Backlog Consolidé'!D5:D64,"Réalisation",'Backlog Consolidé'!K5:K64,"En cours") -> 1 | E29: =COUNTIFS('Backlog Consolidé'!D5:D64,"Réalisation",'Backlog Consolidé'!K5:K64,"A faire") -> 8 | F29: =IF(B29=0,0,C29/B29) -> 0.25
A30: Intégration | B30: =COUNTIF('Backlog Consolidé'!D5:D64,"Intégration") -> 4 | C30: =COUNTIFS('Backlog Consolidé'!D5:D64,"Intégration",'Backlog Consolidé'!K5:K64,"Terminé") -> 1 | D30: =COUNTIFS('Backlog Consolidé'!D5:D64,"Intégration",'Backlog Consolidé'!K5:K64,"En cours") -> 0 | E30: =COUNTIFS('Backlog Consolidé'!D5:D64,"Intégration",'Backlog Consolidé'!K5:K64,"A faire") -> 3 | F30: =IF(B30=0,0,C30/B30) -> 0.25
A31: Recette | B31: =COUNTIF('Backlog Consolidé'!D5:D64,"Recette") -> 15 | C31: =COUNTIFS('Backlog Consolidé'!D5:D64,"Recette",'Backlog Consolidé'!K5:K64,"Terminé") -> 0 | D31: =COUNTIFS('Backlog Consolidé'!D5:D64,"Recette",'Backlog Consolidé'!K5:K64,"En cours") -> 2 | E31: =COUNTIFS('Backlog Consolidé'!D5:D64,"Recette",'Backlog Consolidé'!K5:K64,"A faire") -> 13 | F31: =IF(B31=0,0,C31/B31) -> 0
A32: Déploiement | B32: =COUNTIF('Backlog Consolidé'!D5:D64,"Déploiement") -> 8 | C32: =COUNTIFS('Backlog Consolidé'!D5:D64,"Déploiement",'Backlog Consolidé'!K5:K64,"Terminé") -> 0 | D32: =COUNTIFS('Backlog Consolidé'!D5:D64,"Déploiement",'Backlog Consolidé'!K5:K64,"En cours") -> 0 | E32: =COUNTIFS('Backlog Consolidé'!D5:D64,"Déploiement",'Backlog Consolidé'!K5:K64,"A faire") -> 8 | F32: =IF(B32=0,0,C32/B32) -> 0

Sheet Référentiel Projets
A1: REFERENTIEL DES PROJETS DU PORTEFEUILLE
A3: Code Projet | B3: Nom du Projet | C3: Chef de Projet | D3: Phase Courante | E3: Date Début | F3: Date Fin Prévue | G3: Priorité
A4: PROJ-001 | B4: Refonte SI Gestion des Incidents | C4: M. Dupont | D4: Conception Générale | E4: 01/03/2025 | F4: 30/09/2025 | G4: P1
A5: PROJ-002 | B5: Migration Data Warehouse Cloud | C5: Mme Martin | D5: Expression des Besoins | E5: 01/04/2025 | F5: 31/12/2025 | G5: P2
A6: PROJ-003 | B6: Portail Self-Service Utilisateurs | C6: M. Bernard | D6: Recette | E6: 01/01/2025 | F6: 15/07/2025 | G6: P1
A7: PROJ-004 | B7: Tableau de Bord BI / Reporting Exécutif | C7: M. Leroy | D7: Réalisation | E7: 01/05/2025 | F7: 28/02/2026 | G7: P2
