Workbook

Sheet 00_LEGENDE
A1: LÉGENDE — GRHADES E-Commerce B2C | Odoo eCommerce+CRM+Marketing+Stock+Compta | Modules Python custom
A2: ⚠ Ne pas modifier cet onglet sans validation du chef de projet
A4: Catégorie
B5: Fonctionnel
B6: Non-fonctionnel
B7: Réglementaire
B8: Technique
B9: Sécurité
A11: Priorité
B12: Critique
B13: Haute
B14: Moyenne
B15: Faible
A17: Source
B18: Client
B19: MOA
B20: MOE
B21: Réglementaire
B22: Interne
A24: Phase V-cycle
B25: Définition
B26: Conception
B27: Réalisation
B28: Tests
B29: Recette
B30: Déploiement
A32: Statut Exigence
B33: En attente
B34: Validé
B35: Gelé
B36: Abandonné
B37: En révision
A39: Statut Spécification
B40: En attente
B41: Validé
B42: En cours
B43: Terminé
B44: Rejeté
A46: Modules Odoo concernés
B47: Odoo eCommerce
...

Sheet 01_EXIGENCES
A1: REGISTRE DES EXIGENCES — GRHADES E-Commerce B2C Odoo+Python (30 exigences)
A2: ID_EXG | B2: Catégorie | C2: Titre | D2: Description | E2: Priorité | F2: Source | G2: Phase V-cycle | H2: Statut | I2: Responsable | J2: Date validation | K2: ID_SPEC lié | L2: ID_TEST lié | M2: Taux couv. | N2: Commentaires
A3: EXG-001 | B3: Fonctionnel | C3: Catalogue produits B2C avec variantes | D3: Le site e-commerce doit afficher un catalogue produits avec variantes (couleur, taille, capacité). Chaque fiche produit affiche : images, description, prix TTC, disponibilité stock, avis clients. | E3: Critique | F3: Client | G3: Définition | H3: Validé | I3: M. Karim (MOA) | J3: 08/01/2026 | K3: SPEC-001, SPEC-002 | L3: TST-001, TST-002 | N3: Validé en atelier du 08/01/2026
A4: EXG-002 | B4: Fonctionnel | C4: Panier d'achat et tunnel de commande | D4: L'utilisateur peut ajouter des articles au panier, modifier les quantités, supprimer des articles, visualiser le récapitulatif (sous-total, frais de port, TVA, total TTC) et passer à l'étape de paiement. | E4: Critique | F4: Client | G4: Définition | H4: Validé | I4: M. Karim (MOA) | J4: 08/01/2026 | K4: SPEC-003, SPEC-004 | L4: TST-003
A5: EXG-003 | B5: Fonctionnel | C5: Paiement en ligne sécurisé | D5: Le site accepte le paiement par CB (Stripe), virement bancaire et paiement à la livraison (contre-remboursement). Le module Odoo Payment custom gère la configuration des acquéreurs. | E5: Critique | F5: Client | G5: Définition | H5: Validé | I5: Mme. Sara (MOA) | J5: 10/01/2026 | K5: SPEC-005 | L5: TST-004 | N5: Module Odoo custom grhades_payment
A6: EXG-004 | B6: Fonctionnel | C6: Espace client — Compte personnel | D6: Chaque client dispose d'un espace personnel affichant : historique des commandes, statut de livraison, factures téléchargeables en PDF, gestion des adresses de livraison et de facturation. | E6: Haute | F6: Client | G6: Définition | H6: Validé | I6: M. Karim (MOA) | J6: 10/01/2026 | K6: SPEC-006 | L6: TST-005 | N6: Portail Odoo standard + custom
A7: EXG-005 | B7: Fonctionnel | C7: Gestion des stocks en temps réel | D7: Le stock disponible affiché sur le site est synchronisé avec le module Stock Odoo. Quand un produit est en rupture, il est automatiquement grisé avec le message 'Rupture de stock — bientôt disponible'. | E7: Critique | F7: MOA | G7: Définition | H7: Validé | I7: M. Yassine (Tech) | J7: 12/01/2026 | K7: SPEC-007 | L7: TST-006 | N7: Module Odoo custom grhades_stock_website
A8: EXG-006 | B8: Fonctionnel | C8: Gestion des commandes et bons de livraison | D8: À chaque commande validée, Odoo crée automatiquement un bon de préparation (stock.picking) dans le module Stock. Le picking est traité par l'entrepôt et déclenche l'email d'expédition au client. | E8: Critique | F8: MOA | G8: Définition | H8: Validé | I8: M. Yassine (Tech) | J8: 12/01/2026 | K8: SPEC-008 | L8: TST-007
A9: EXG-007 | B9: Fonctionnel | C9: Facturation automatique B2C | D9: Toute commande confirmée génère automatiquement une facture dans Odoo Comptabilité. La facture est envoyée par email au client au format PDF et enregistrée dans son espace personnel. | E9: Critique | F9: MOA | G9: Définition | H9: Validé | I9: Mme. Sara (MOA) | J9: 15/01/2026 | K9: SPEC-009 | L9: TST-008 | N9: Module Account Odoo standard + trigger custom
A10: EXG-008 | B10: Fonctionnel | C10: Emails transactionnels automatisés | D10: Le système envoie automatiquement par email : confirmation de commande, confirmation d'expédition avec numéro de suivi, facture PDF, confirmation de retour et remboursement. | E10: Haute | F10: MOA | G10: Définition | H10: Validé | I10: M. Karim (MOA) | J10: 15/01/2026 | K10: SPEC-010 | L10: TST-009 | N10: Templates mail.template Odoo custom
A11: EXG-009 | B11: Fonctionnel | C11: Gestion des retours et remboursements | D11: Le client peut initier une demande de retour depuis son espace dans les 30 jours suivant la réception. Odoo génère un bon de retour, l'avoir comptable et déclenche le remboursement CB automatiquement. | E11: Haute | F11: Client | G11: Définition | H11: Validé | I11: M. Karim (MOA) | J11: 18/01/2026 | K11: SPEC-011 | L11: TST-010 | N11: Module Odoo custom grhades_returns
A12: EXG-010 | B12: Fonctionnel | C12: Moteur de recherche produits avec filtres | D12: La barre de recherche permet une recherche par mots-clés, avec filtres par catégorie, fourchette de prix, disponibilité et marque. Les résultats sont paginés (24 produits par page) et triables. | E12: Haute | F12: Client | G12: Définition | H12: Validé | I12: M. Amine (Dev) | J12: 18/01/2026 | K12: SPEC-012 | L12: TST-011 | N12: Odoo eCommerce search natif + améliorations custom
A13: EXG-011 | B13: Fonctionnel | C13: Programme de fidélité — Points et bons | D13: Les clients accumulent 1 point par euro dépensé. À partir de 100 points, ils peuvent générer un bon de réduction de 5€. Le module Odoo Loyalty est configuré et étendu par un module custom. | E13: Moyenne | F13: Client | G13: Définition | H13: Validé | I13: M. Karim (MOA) | J13: 20/01/2026 | K13: SPEC-013 | L13: TST-012 | N13: Module Odoo Loyalty + grhades_loyalty_custom
A14: EXG-012 | B14: Fonctionnel | C14: Avis et notes produits | D14: Les clients ayant passé commande peuvent déposer un avis (note de 1 à 5 étoiles + commentaire texte). Les avis sont soumis à modération avant publication. La note moyenne est affichée sur la fiche produit. | E14: Moyenne | F14: Client | G14: Définition | H14: Validé | I14: M. Amine (Dev) | J14: 20/01/2026 | K14: SPEC-014 | L14: TST-013 | N14: Modèle product.review custom Odoo
A15: EXG-013 | B15: Fonctionnel | C15: Codes promotionnels et remises | D15: L'équipe marketing peut créer des codes promo (pourcentage ou montant fixe, date de validité, nombre d'utilisations maximum, produits éligibles) dans le module Odoo Coupon. | E15: Haute | F15: MOA | G15: Définition | H15: Validé | I15: Mme. Sara (MOA) | J15: 22/01/2026 | K15: SPEC-015 | L15: TST-014 | N15: Module Odoo Coupon standard + grhades_coupon_custom
A16: EXG-014 | B16: Fonctionnel | C16: Suivi de livraison intégré | D16: Après expédition, le client reçoit un email avec le numéro de suivi et peut consulter le statut de livraison directement dans son espace client (lien vers le site du transporteur). | E16: Haute | F16: Client | G16: Définition | H16: Validé | I16: M. Yassine (Tech) | J16: 22/01/2026 | K16: SPEC-016 | L16: TST-015 | N16: Module Odoo custom grhades_delivery_tracking
A17: EXG-015 | B17: Fonctionnel | C17: CRM — Capture et qualification des leads | D17: Tout formulaire de contact soumis sur le site crée automatiquement un lead dans le module CRM Odoo. Le lead est assigné selon les règles de routage configurées (canal, catégorie produit, zone géographique). | E17: Haute | F17: MOA | G17: Définition | H17: Validé | I17: Mme. Sara (MOA) | J17: 25/01/2026 | K17: SPEC-017 | L17: TST-016 | N17: Module CRM Odoo + grhades_crm_website
A18: EXG-016 | B18: Fonctionnel | C18: Campagnes emailing marketing | D18: L'équipe marketing peut créer, planifier et envoyer des campagnes emailing depuis Odoo Marketing (Mass Mailing). Segments disponibles : nouveaux clients, clients inactifs +60j, paniers abandonnés. | E18: Moyenne | F18: MOA | G18: Conception | H18: Validé | I18: Mme. Sara (MOA) | J18: 05/02/2026 | K18: SPEC-018 | L18: TST-017 | N18: Module Odoo Mass Mailing + grhades_marketing_automation
A19: EXG-017 | B19: Fonctionnel | C19: Récupération des paniers abandonnés | D19: Un module Odoo custom détecte les paniers non validés depuis plus de 2 heures et déclenche une séquence d'emails de relance (J+2h, J+1, J+3) via Odoo Marketing Automation. | E19: Haute | F19: MOA | G19: Conception | H19: Validé | I19: M. Amine (Dev) | J19: 08/02/2026 | K19: SPEC-019 | L19: TST-018 | N19: Module grhades_abandoned_cart — KPI clé
A20: EXG-018 | B20: Fonctionnel | C20: Tableau de bord KPI e-commerce | D20: Le responsable e-commerce dispose d'un dashboard Odoo affichant : CA du jour/mois/année, nombre de commandes, panier moyen, taux de conversion, top 10 produits, taux de retour. | E20: Moyenne | F20: MOA | G20: Conception | H20: Validé | I20: Mme. Sara (MOA) | J20: 10/02/2026 | K20: SPEC-020 | L20: TST-019 | N20: Dashboard Odoo custom views + computed fields Python
... A26: EXG-024 | B26: Fonctionnel | C26: Multilingue Français / Anglais | D26: Le site est disponible en français (langue par défaut) et en anglais. Le visiteur peut changer de langue depuis le header. Les traductions produits sont gérées dans Odoo (ir.translation). | E26: Moyenne | F26: Client | G26: Conception | H26: Validé | I26: M. Amine (Dev) | J26: 22/02/2026 | K26: SPEC-026 | L26: TST-025 | N26: Langues activées : fr_FR, en_US
A27: EXG-025 | B27: Technique | C27: Module Odoo custom — Tableau de bord avancé | D27: Développement du module Python Odoo grhades_dashboard : modèles computed fields pour les KPIs e-commerce, vues Odoo (ir.ui.view), graphes OWL. Tests unitaires obligatoires (coverage > 80%). | E27: Haute | F27: MOE | G27: Réalisation | H27: En cours | I27: M. Amine (Dev) | K27: SPEC-027 | N27: Sprint 3 en cours — graphes CA terminés
A28: EXG-026 | B28: Technique | C28: Module Odoo custom — Récupération paniers abandonnés | D28: Développement du module Python grhades_abandoned_cart : modèle sale.order avec champ state='cart', cron Odoo détectant les paniers inactifs, séquence email via marketing.automation. | E28: Haute | F28: MOE | G28: Réalisation | H28: En cours | I28: M. Amine (Dev) | K28: SPEC-028 | N28: Sprint 3 — cron fonctionnel, séquence email en dev
A29: EXG-027 | B29: Technique | C29: Module Odoo custom — Avis produits | D29: Développement du module Python grhades_product_review : modèle product.review lié à product.template et res.partner, interface de modération dans le back-office Odoo, widget étoiles en front. | E29: Moyenne | F29: MOE | G29: Réalisation | H29: En cours | I29: M. Amine (Dev) | K29: SPEC-029 | N29: Sprint 3 — modèle et vues back-office terminés
A30: EXG-028 | B30: Technique | C30: Module Odoo custom — RGPD | D30: Développement du module Python grhades_rgpd : endpoint /rgpd/oubli (anonymisation res.partner), endpoint /rgpd/export (JSON données personnelles), journal des accès (res.log), bandeau cookies OWL. | E30: Critique | F30: MOE | G30: Réalisation | H30: En cours | I30: M. Yassine (Tech) | K30: SPEC-030 | N30: Sprint 3 — anonymisation OK, export en dev
A31: EXG-029 | B31: Technique | C31: Module Odoo custom — Remises et coupons avancés | D31: Développement du module Python grhades_coupon_custom : extension du module Coupon natif pour ajouter les règles de cumul (code promo + fidélité), le plafonnement des remises et les alertes d'expiration. | E31: Haute | F31: MOE | G31: Réalisation | H31: En attente | I31: M. Amine (Dev) | K31: SPEC-031 | N31: Sprint 4 — démarrage le 27/04/2026
A32: EXG-030 | B32: Non-fonctionnel | C32: Sauvegarde automatique et plan de reprise | D32: Sauvegarde quotidienne automatique de la base PostgreSQL Odoo par script Python (cron 02h00), compression gzip, stockage sur NAS interne avec rétention 30 jours. Test de restauration mensuel documenté. | E32: Critique | F32: MOE | G32: Réalisation | H32: En attente | I32: M. Yassine (Tech) | K32: SPEC-032 | N32: Sprint 4 — NAS en cours de configuration

Sheet 02_SPECIFICATIONS
A1: REGISTRE DES SPÉCIFICATIONS TECHNIQUES — GRHADES (34 spécifications)
A2: ID_SPEC | B2: ID_EXG lié | C2: Phase | D2: Titre | E2: Description technique détaillée | F2: Module Odoo/Python | G2: Priorité | H2: Statut | I2: Responsable | J2: Date livraison | K2: ID_SPEC parent | L2: ID_TEST lié | M2: Commentaires
A3: SPEC-001 | B3: EXG-001 | C3: Conception | D3: Fiche produit — Variantes et galerie images | E3: Utilisation du module Odoo eCommerce natif pour les variantes (product.template + product.product). Le module grhades_product_display surcharge le template website.product_detail pour ajouter : sélecteur de variantes dynamique (OWL), galerie lightbox, badge 'Nouveau' (champ is_new calculé si date création < 30 jours). | F3: Odoo eCommerce + OWL + Python | G3: Critique | H3: Validé | I3: M. Amine (Dev) | J3: 10/03/2026 | L3: TST-001 | M3: Surcharge XML templates Odoo — attention aux mises à jour Odoo
A4: SPEC-002 | B4: EXG-001 | C4: Conception | D4: Fiche produit — Avis clients et note moyenne | E4: Affichage de la note moyenne (moyenne des product.review validés) et des derniers avis sous la description produit. Widget étoiles développé en OWL. Si aucun avis : message 'Soyez le premier à donner votre avis'. | F4: Odoo eCommerce + OWL + Python | G4: Haute | H4: Validé | I4: M. Amine (Dev) | J4: 10/03/2026 | L4: TST-002 | M4: Dépend de SPEC-029 (module grhades_product_review)
A5: SPEC-003 | B5: EXG-002 | C5: Conception | D5: Panier — Ajout article et persistance | E5: Utilisation du mécanisme natif Odoo sale.order (état draft = panier). Surcharge du controller website_sale pour ajouter : vérification stock temps réel avant ajout (appel stock.quant), message d'avertissement si stock < 3 unités. | F5: Odoo eCommerce + Python controller | G5: Critique | H5: Validé | I5: M. Amine (Dev) | J5: 12/03/2026 | L5: TST-003 | M5: Controller Python : /shop/cart/update surcharge
A6: SPEC-004 | B6: EXG-002 | C6: Conception | D6: Panier — Récapitulatif et frais de port | E6: Affichage du récapitulatif panier avec calcul automatique des frais de port selon le module Odoo Delivery (delivery.carrier). Frais de port offerts au-delà de 50€ (règle configurable dans l'interface Odoo). | F6: Odoo eCommerce + Delivery | G6: Haute | H6: Validé | I6: M. Amine (Dev) | J6: 12/03/2026 | M6: Paramètre seuil port offert : ir.config_parameter
A7: SPEC-005 | B7: EXG-003 | C7: Conception | D7: Paiement — Module Odoo custom Stripe | E7: Développement du module grhades_payment_stripe héritant de payment.provider Odoo. Intégration Stripe Payment Element (hosted fields). Gestion webhook Stripe (payment_intent.succeeded, payment_intent.failed) via controller Python /payment/stripe/webhook. | F7: Python Odoo + Stripe API | G7: Critique | H7: Validé | I7: M. Yassine (Tech) | J7: 15/03/2026 | L7: TST-004 | M7: Clés API Stripe dans ir.config_parameter (chiffrées)
A8: SPEC-006 | B8: EXG-004 | C8: Conception | D8: Espace client — Portail Odoo étendu | E8: Extension du portail Odoo standard (portal.mixin) via le module grhades_customer_portal. Ajout des pages : /my/loyalty (points fidélité + historique), /my/reviews (avis déposés), /my/returns (demandes de retour). Navigation par onglets. | F8: Odoo Portal + Python | G8: Haute | H8: Validé | I8: M. Amine (Dev) | J8: 18/03/2026 | L8: TST-005 | M8: Héritage des templates portal.html Odoo
A9: SPEC-007 | B9: EXG-005 | C9: Conception | D9: Stock — Affichage disponibilité temps réel | E9: Module grhades_stock_website : computed field qty_website_available sur product.product (= qty_on_hand - qty_reserved). Seuil d'affichage configurable : > 5 = 'En stock', 1-5 = 'Stock limité' (badge orange), 0 = 'Rupture' (grisé). Mise à jour toutes les 5 min (cron Odoo). | F9: Python Odoo ORM + Computed fields | G9: Critique | H9: Validé | I9: M. Yassine (Tech) | J9: 20/03/2026 | L9: TST-006 | M9: Cron : ir.cron toutes les 5 min
A10: SPEC-008 | B10: EXG-006 | C10: Conception | D10: Stock — Automatisation bon de livraison | E10: Post-hook Python sur sale.order.action_confirm() : création automatique du stock.picking de type outgoing. Règle de réservation configurée sur l'entrepôt GRHADES (reservation = immédiate si stock disponible). Notification email picking créé au responsable entrepôt. | F10: Python Odoo ORM + Stock | G10: Critique | H10: Validé | I10: M. Yassine (Tech) | J10: 20/03/2026 | L10: TST-007 | M10: Override méthode action_confirm dans module grhades_sale_custom
A11: SPEC-009 | B11: EXG-007 | C11: Conception | D11: Comptabilité — Génération facture automatique | E11: Post-hook Python sur sale.order.action_confirm() : appel de _create_invoices() Odoo pour générer account.move (type out_invoice). Validation automatique (action_post()) et envoi email PDF via mail.template 'Votre facture GRHADES'. | F11: Python Odoo ORM + Account | G11: Critique | H11: Validé | I11: Mme. Sara (MOA) | J11: 22/03/2026 | L11: TST-008 | M11: Journal ventes configuré dans Odoo Comptabilité
A12: SPEC-010 | B12: EXG-008 | C12: Conception | D12: Emails — Templates transactionnels custom | E12: Création de 5 mail.template Odoo dans le module grhades_mail_templates : (1) Confirmation commande avec récapitulatif articles, (2) Expédition avec numéro tracking, (3) Facture PDF en pièce jointe, (4) Confirmation retour accepté, (5) Remboursement effectué. | F12: Odoo Mail + QWeb templates | G12: Haute | H12: Validé | I12: M. Amine (Dev) | J12: 25/03/2026 | L12: TST-009 | M12: Templates QWeb HTML responsive — test sur Litmus
A13: SPEC-011 | B13: EXG-009 | C13: Conception | D13: Retours — Workflow complet Odoo | E13: Module grhades_returns : formulaire /my/return/new (sélection articles, motif, photo). Création stock.return.picking + account.move.reversal (avoir). Si paiement Stripe : appel Stripe Refund API depuis Python. Statuts : Demandé → Approuvé → Réceptionné → Remboursé. | F13: Python Odoo + Stripe Refund | G13: Haute | H13: Validé | I13: M. Yassine (Tech) | J13: 28/03/2026 | L13: TST-010 | M13: Délai remboursement : 5-10 jours ouvrés (Stripe)
A14: SPEC-012 | B14: EXG-010 | C14: Conception | D14: Recherche — Amélioration moteur Odoo | E14: Extension du module Odoo eCommerce search : ajout filtres de prix (range slider OWL), filtre disponibilité (stock > 0), filtre marque (attribut product.attribute). Tri par : pertinence (défaut), prix croissant/décroissant, nouveautés, meilleures ventes (champ sales_count). | F14: Odoo eCommerce + OWL + Python | G14: Haute | H14: Validé | I14: M. Amine (Dev) | J14: 01/04/2026 | L14: TST-011 | M14: sales_count : computed field sur product.template
A15: SPEC-013 | B15: EXG-011 | C15: Conception | D15: Fidélité — Configuration module Odoo Loyalty | E15: Configuration du module Odoo Loyalty : programme 'GRHADES Rewards' (1€ = 1 point, 100 points = bon 5€). Extension grhades_loyalty_custom : affichage points dans le header (widget OWL), notification email à chaque gain de points, alerte solde suffisant pour bon. | F15: Odoo Loyalty + OWL + Python | G15: Moyenne | H15: Validé | I15: M. Karim (MOA) | J15: 05/04/2026 | L15: TST-012 | M15: Points calculés sur account.move posted
A16: SPEC-014 | B16: EXG-012 | C16: Conception | D16: Avis produits — Modèle et interface | E16: Développement modèle product.review (module grhades_product_review) : champs product_id, partner_id, rating (1-5), title, body, state (pending/published/rejected), date. Interface modération Odoo back-office (tree + form views). Contrainte : 1 avis par client par produit commandé. | F16: Python Odoo ORM + Views | G16: Moyenne | H16: Validé | I16: M. Amine (Dev) | J16: 08/04/2026 | L16: TST-013 | M16: Vérification commande : SQL check sur sale.order.line
A17: SPEC-015 | B17: EXG-013 | C17: Conception | D17: Coupons — Extension règles de cumul | E17: Module grhades_coupon_custom : extension coupon.rule pour ajouter champ cumul_with_loyalty (booléen). Override de _check_promo_applicability pour gérer le cumul code promo + points fidélité. Plafonnement remise totale à 30% du panier configurable. | F17: Python Odoo ORM + Coupon | G17: Haute | H17: Validé | I17: M. Karim (MOA) | J17: 10/04/2026 | L17: TST-014 | M17: Dépend de SPEC-013 (fidélité)
A18: SPEC-016 | B18: EXG-014 | C18: Conception | D18: Livraison — Tracking dans l'espace client | E18: Module grhades_delivery_tracking : champ tracking_url computed sur stock.picking générant l'URL de suivi (Colissimo, Chronopost selon delivery.carrier). Affichage dans /my/orders avec statut visuel (timeline OWL). Email automatique à chaque changement de statut. | F18: Python Odoo + OWL | G18: Haute | H18: Validé | I18: M. Amine (Dev) | J18: 12/04/2026 | L18: TST-015 | M18: API Colissimo : module séparé sprint 4
... A28: SPEC-026 | B28: EXG-024 | C28: Conception | D28: Multilingue — Configuration Odoo i18n | E28: Activation des langues fr_FR (défaut) et en_US dans Odoo (res.lang). Traductions des champs produits via ir.translation. Composant OWL sélecteur de langue dans le header. Détection automatique langue navigateur (HTTP Accept-Language). Traductions des templates email dans les 2 langues. | F28: Odoo i18n + ir.translation | G28: Moyenne | H28: Validé | I28: M. Amine (Dev) | J28: 02/05/2026 | L28: TST-025 | M28: Fichiers .po à générer depuis le back-office Odoo
A29: SPEC-027 | B29: EXG-025 | C29: Réalisation | D29: Module grhades_dashboard — Développement | E29: Structure module : __manifest__.py (dépendances : sale, account, stock), modèles Python (grhades/models/dashboard.py), vues XML (grhades/views/dashboard_views.xml), assets OWL (grhades/static/src/). Tests unitaires : tests/test_dashboard.py (coverage > 80% obligatoire avant merge). | F29: Python Odoo + OWL + Tests | G29: Haute | H29: En cours | I29: M. Amine (Dev) | J29: 05/05/2026 | M29: Sprint 3 — graphes CA et commandes terminés
A30: SPEC-028 | B30: EXG-026 | C30: Réalisation | D30: Module grhades_abandoned_cart — Développement | E30: Structure : modèle sale.order étendu (champ is_abandoned computed), cron ir.cron (intervalle 1h), méthode _send_recovery_sequence() appelant marketing.automation. Tests : simulation paniers avec différentes anciennetés, vérification non-envoi si commande validée entre-temps. | F30: Python Odoo + Cron + Tests | G30: Haute | H30: En cours | I30: M. Amine (Dev) | J30: 08/05/2026 | M30: Cron fonctionnel — séquence email en dev
A31: SPEC-029 | B31: EXG-027 | C31: Réalisation | D31: Module grhades_product_review — Développement | E31: Modèle product.review : _sql_constraints (unique partner_id + product_id par commande), méthode action_publish() avec notification email au modérateur, compute _compute_average_rating sur product.template. Front : formulaire QWeb /shop/product/{id}/review, widget étoiles OWL. | F31: Python Odoo ORM + QWeb + OWL | G31: Moyenne | H31: En cours | I31: M. Amine (Dev) | J31: 10/05/2026 | M31: Modèle et vues back-office terminés — front en dev
A32: SPEC-030 | B32: EXG-028 | C32: Réalisation | D32: Module grhades_rgpd — Développement | E32: Développement des routes Python (http.route) : GET /rgpd/export → génération JSON (res.partner + commandes + factures du partenaire connecté), POST /rgpd/oubli → write({'name': 'Anonyme XXXXXXXX', 'email': f'anonyme_{hash}@grhades.dz', 'phone': False, 'street': False}). Log dans grhades.rgpd.log (date, action, partner_id). | F32: Python Odoo + Routes HTTP | G32: Critique | H32: En cours | I32: M. Yassine (Tech) | J32: 12/05/2026 | M32: Anonymisation OK — export en dev
A33: SPEC-031 | B33: EXG-029 | C33: Réalisation | D33: Module grhades_coupon_custom — Développement | E33: Extension coupon.program : ajout champ max_cumul_percentage (défaut 30%). Override _check_promo_applicability() : calcul cumul remises courantes + nouvelle remise, rejet si > max_cumul_percentage. Interface Odoo : affichage du plafond dans la fiche programme de réduction. | F33: Python Odoo ORM + Coupon | G33: Haute | H33: En attente | I33: M. Amine (Dev) | J33: 18/05/2026 | M33: Démarrage sprint 4 le 27/04/2026
A34: SPEC-032 | B34: EXG-030 | C34: Réalisation | D34: Script Python — Sauvegarde automatique | E34: Script Python backup_odoo.py : subprocess.run(['pg_dump', ...]) avec compression gzip, nommage GRHADES_odoo_{date}.sql.gz, copie sur NAS via shutil/SMB. Cron système (crontab 02h00). En cas d'échec : envoi email alerte via smtplib. Log résultat dans /var/log/grhades/backup.log. | F34: Python + PostgreSQL + NAS | G34: Critique | H34: En attente | I34: M. Yassine (Tech) | J34: 20/05/2026 | M34: NAS en cours de configuration IT
A35: SPEC-033 | B35: EXG-018 | C35: Réalisation | D35: Dashboard — Rapport hebdomadaire automatique | E35: Extension grhades_dashboard : cron Odoo chaque lundi 07h00 générant un rapport PDF (QWeb report) synthétisant les KPIs de la semaine écoulée. Envoi automatique par email aux destinataires configurés (Many2many res.users dans ir.config_parameter). | F35: Python Odoo + QWeb Report | G35: Moyenne | H35: En attente | I35: M. Amine (Dev) | J35: 22/05/2026 | M35: Dépend de SPEC-027 (dashboard)
A36: SPEC-034 | B36: EXG-016 | C36: Réalisation | D36: Marketing — Automatisation campagnes relance | E36: Configuration avancée Odoo Marketing Automation : workflow 'Réactivation clients inactifs' (trigger : partner inactif +60j, action : email J0 + SMS J+7 si pas d'ouverture). Module grhades_marketing_custom ajoute le champ sms_enabled et intègre l'envoi SMS via passerelle configurée dans ir.config_parameter. | F36: Odoo Marketing Automation + Python | G36: Moyenne | H36: En attente | I36: M. Amine (Dev) | J36: 25/05/2026 | M36: Passerelle SMS à sélectionner (Twilio ou OVH SMS)

Sheet 03_SYNTHESE_PHASE
A1: TABLEAU DE BORD — Avancement par Phase (Exigences & Spécifications)
A2: ⟳ Formules automatiques — se recalcule à l'ouverture
A3: Phase V-cycle | B3: EXG Total | C3: EXG Validées | D3: EXG En attente | E3: EXG % | F3: SPEC Total | G3: SPEC Validées/Term. | H3: SPEC En cours | I3: SPEC % | J3: Commentaires
A4: Définition | B4: =COUNTIF('01_EXIGENCES'!$G$3:$G$200,"Définition") | C4: =COUNTIFS('01_EXIGENCES'!$G$3:$G$200,"Définition",'01_EXIGENCES'!$H$3:$H$200,"Validé") | D4: =COUNTIFS('01_EXIGENCES'!$G$3:$G$200,"Définition",'01_EXIGENCES'!$H$3:$H$200,"En attente") | E4: =IF(B4=0,0,C4/B4) | F4: =COUNTIF('02_SPECIFICATIONS'!$C$3:$C$200,"Définition") | G4: =COUNTIFS('02_SPECIFICATIONS'!$C$3:$C$200,"Définition",'02_SPECIFICATIONS'!$H$3:$H$200,"Validé")+COUNTIFS('02_SPECIFICATIONS'!$C$3:$C$200,"Définition",'02_SPECIFICATIONS'!$H$3:$H$200,"Terminé") | H4: =COUNTIFS('02_SPECIFICATIONS'!$C$3:$C$200,"Définition",'02_SPECIFICATIONS'!$H$3:$H$200,"En cours") | I4: =IF(F4=0,0,G4/F4) | J4: 15 exigences fonctionnelles — toutes validées ✓
A5: Conception | B5: =COUNTIF('01_EXIGENCES'!$G$3:$G$200,"Conception") | C5: =COUNTIFS('01_EXIGENCES'!$G$3:$G$200,"Conception",'01_EXIGENCES'!$H$3:$H$200,"Validé") | D5: =COUNTIFS('01_EXIGENCES'!$G$3:$G$200,"Conception",'01_EXIGENCES'!$H$3:$H$200,"En attente") | E5: =IF(B5=0,0,C5/B5) | F5: =COUNTIF('02_SPECIFICATIONS'!$C$3:$C$200,"Conception") | G5: =COUNTIFS('02_SPECIFICATIONS'!$C$3:$C$200,"Conception",'02_SPECIFICATIONS'!$H$3:$H$200,"Validé")+COUNTIFS('02_SPECIFICATIONS'!$C$3:$C$200,"Conception",'02_SPECIFICATIONS'!$H$3:$H$200,"Terminé") | H5: =COUNTIFS('02_SPECIFICATIONS'!$C$3:$C$200,"Conception",'02_SPECIFICATIONS'!$H$3:$H$200,"En cours") | I5: =IF(F5=0,0,G5/F5) | J5: 15 exigences architecture & sécurité — toutes validées ✓
A6: Réalisation | B6: =COUNTIF('01_EXIGENCES'!$G$3:$G$200,"Réalisation") | C6: =COUNTIFS('01_EXIGENCES'!$G$3:$G$200,"Réalisation",'01_EXIGENCES'!$H$3:$H$200,"Validé") | D6: =COUNTIFS('01_EXIGENCES'!$G$3:$G$200,"Réalisation",'01_EXIGENCES'!$H$3:$H$200,"En attente") | E6: =IF(B6=0,0,C6/B6) | F6: =COUNTIF('02_SPECIFICATIONS'!$C$3:$C$200,"Réalisation") | G6: =COUNTIFS('02_SPECIFICATIONS'!$C$3:$C$200,"Réalisation",'02_SPECIFICATIONS'!$H$3:$H$200,"Validé")+COUNTIFS('02_SPECIFICATIONS'!$C$3:$C$200,"Réalisation",'02_SPECIFICATIONS'!$H$3:$H$200,"Terminé") | H6: =COUNTIFS('02_SPECIFICATIONS'!$C$3:$C$200,"Réalisation",'02_SPECIFICATIONS'!$H$3:$H$200,"En cours") | I6: =IF(F6=0,0,G6/F6) | J6: 6 exigences techniques — modules Python custom en cours
A7: Tests | B7: =COUNTIF('01_EXIGENCES'!$G$3:$G$200,"Tests") | C7: =COUNTIFS('01_EXIGENCES'!$G$3:$G$200,"Tests",'01_EXIGENCES'!$H$3:$H$200,"Validé") | D7: =COUNTIFS('01_EXIGENCES'!$G$3:$G$200,"Tests",'01_EXIGENCES'!$H$3:$H$200,"En attente") | E7: =IF(B7=0,0,C7/B7) | F7: =COUNTIF('02_SPECIFICATIONS'!$C$3:$C$200,"Tests") | G7: =COUNTIFS('02_SPECIFICATIONS'!$C$3:$C$200,"Tests",'02_SPECIFICATIONS'!$H$3:$H$200,"Validé")+COUNTIFS('02_SPECIFICATIONS'!$C$3:$C$200,"Tests",'02_SPECIFICATIONS'!$H$3:$H$200,"Terminé") | H7: =COUNTIFS('02_SPECIFICATIONS'!$C$3:$C$200,"Tests",'02_SPECIFICATIONS'!$H$3:$H$200,"En cours") | I7: =IF(F7=0,0,G7/F7) | J7: Tests fonctionnels en cours — phase active
A8: Recette | B8: =COUNTIF('01_EXIGENCES'!$G$3:$G$200,"Recette") | C8: =COUNTIFS('01_EXIGENCES'!$G$3:$G$200,"Recette",'01_EXIGENCES'!$H$3:$H$200,"Validé") | D8: =COUNTIFS('01_EXIGENCES'!$G$3:$G$200,"Recette",'01_EXIGENCES'!$H$3:$H$200,"En attente") | E8: =IF(B8=0,0,C8/B8) | F8: =COUNTIF('02_SPECIFICATIONS'!$C$3:$C$200,"Recette") | G8: =COUNTIFS('02_SPECIFICATIONS'!$C$3:$C$200,"Recette",'02_SPECIFICATIONS'!$H$3:$H$200,"Validé")+COUNTIFS('02_SPECIFICATIONS'!$C$3:$C$200,"Recette",'02_SPECIFICATIONS'!$H$3:$H$200,"Terminé") | H8: =COUNTIFS('02_SPECIFICATIONS'!$C$3:$C$200,"Recette",'02_SPECIFICATIONS'!$H$3:$H$200,"En cours") | I8: =IF(F8=0,0,G8/F8) | J8: Recette MOA démarrée le 12/04/2026
A9: Déploiement | B9: =COUNTIF('01_EXIGENCES'!$G$3:$G$200,"Déploiement") | C9: =COUNTIFS('01_EXIGENCES'!$G$3:$G$200,"Déploiement",'01_EXIGENCES'!$H$3:$H$200,"Validé") | D9: =COUNTIFS('01_EXIGENCES'!$G$3:$G$200,"Déploiement",'01_EXIGENCES'!$H$3:$H$200,"En attente") | E9: =IF(B9=0,0,C9/B9) | F9: =COUNTIF('02_SPECIFICATIONS'!$C$3:$C$200,"Déploiement") | G9: =COUNTIFS('02_SPECIFICATIONS'!$C$3:$C$200,"Déploiement",'02_SPECIFICATIONS'!$H$3:$H$200,"Validé")+COUNTIFS('02_SPECIFICATIONS'!$C$3:$C$200,"Déploiement",'02_SPECIFICATIONS'!$H$3:$H$200,"Terminé") | H9: =COUNTIFS('02_SPECIFICATIONS'!$C$3:$C$200,"Déploiement",'02_SPECIFICATIONS'!$H$3:$H$200,"En cours") | I9: =IF(F9=0,0,G9/F9) | J9: Planifié mai 2026
A10: TOTAL | B10: =SUM(B4:B9) | C10: =SUM(C4:C9) | D10: =SUM(D4:D9) | E10: =IF(B10=0,0,C10/B10) | F10: =SUM(F4:F9) | G10: =SUM(G4:G9) | H10: =SUM(H4:H9) | I10: =IF(F10=0,0,G10/F10) | J10: Synthèse consolidée toutes phases

Sheet 04_MODULES_CUSTOM
A1: REGISTRE DES MODULES PYTHON ODOO CUSTOM — GRHADES
A2: Nom du module | B2: EXG liées | C2: SPEC liées | D2: Sprint | E2: Statut | F2: Responsable | G2: Date livraison | H2: Description courte
A3: grhades_payment_stripe | B3: EXG-003 | C3: SPEC-005 | D3: S2 | E3: Terminé | F3: M. Yassine | G3: 14/03/2026 | H3: Module paiement Stripe : PaymentIntent, webhook, tokenisation CB
A4: grhades_stock_website | B4: EXG-005 | C4: SPEC-007 | D4: S2 | E4: Terminé | F4: M. Yassine | G4: 20/03/2026 | H4: Disponibilité stock temps réel sur le site : badges En stock / Stock limité / Rupture
A5: grhades_sale_custom | B5: EXG-006, EXG-007 | C5: SPEC-008, SPEC-009 | D5: S2 | E5: Terminé | F5: M. Yassine | G5: 22/03/2026 | H5: Post-hooks sur sale.order.action_confirm : picking + facture automatiques
A6: grhades_mail_templates | B6: EXG-008 | C6: SPEC-010 | D6: S2 | E6: Terminé | F6: M. Amine | G6: 25/03/2026 | H6: 5 templates QWeb email transactionnels (commande, expédition, facture, retour, remboursement)
A7: grhades_returns | B7: EXG-009 | C7: SPEC-011 | D7: S2 | E7: Terminé | F7: M. Yassine | G7: 28/03/2026 | H7: Workflow retours complet : formulaire portail, avoir, remboursement Stripe
A8: grhades_customer_portal | B8: EXG-004 | C8: SPEC-006 | D8: S2 | E8: Terminé | F8: M. Amine | G8: 18/03/2026 | H8: Extension portail Odoo : pages /my/loyalty, /my/reviews, /my/returns
A9: grhades_product_display | B9: EXG-001 | C9: SPEC-001, SPEC-002 | D9: S2 | E9: Terminé | F9: M. Amine | G9: 10/03/2026 | H9: Surcharge templates fiche produit : galerie OWL, sélecteur variantes, badge Nouveau
A10: grhades_loyalty_custom | B10: EXG-011 | C10: SPEC-013 | D10: S3 | E10: En cours | F10: M. Amine | G10: 05/05/2026 | H10: Extension Odoo Loyalty : widget points header, email notification, alerte solde
A11: grhades_product_review | B11: EXG-012 | C11: SPEC-014, SPEC-029 | D11: S3 | E11: En cours | F11: M. Amine | G11: 10/05/2026 | H11: Modèle product.review, interface modération back-office, widget étoiles front
A12: grhades_crm_website | B12: EXG-015 | C12: SPEC-017 | D12: S3 | E12: En cours | F12: M. Amine | G12: 15/04/2026 | H12: Extension formulaire contact : champs UTM, catégorie intérêt, règles assignation CRM
A13: grhades_abandoned_cart | B13: EXG-017 | C13: SPEC-019, SPEC-028 | D13: S3 | E13: En cours | F13: M. Amine | G13: 08/05/2026 | H13: Détection paniers abandonnés + séquence email relance via Marketing Automation
... A21: backup_odoo.py | B21: EXG-030 | C21: SPEC-032 | D21: S4 | E21: En attente | F21: M. Yassine | G21: 20/05/2026 | H21: Script Python cron backup PostgreSQL → NAS, alertes email, rotation 30 jours
